<?xml version="1.0" ?>
<robot name="maze_bot" xmlns:xacro="http://www.ros.org/wiki/xacro">

<!-- <xacro:include filename="$(find maze_bot)/urdf/materials.xacro" /> -->
<xacro:include filename="$(find maze_bot)/urdf/maze_bot.trans" />
<xacro:include filename="$(find maze_bot)/urdf/maze_bot.gazebo" />
<link name="base_link">
  <inertial>
    <origin xyz="-0.0055867824164207045 4.3086649718411453e-17 0.055589318728555964" rpy="0 0 0"/>
    <mass value="3.580002214810765"/>
    <inertia ixx="0.012385" iyy="0.026567" izz="0.035663" ixy="0.0" iyz="0.0" ixz="0.000914"/>
  </inertial>
  <visual>
    <origin xyz="0 0 0" rpy="0 0 0"/>
    <geometry>
      <mesh filename="package://maze_bot/meshes/base_link.stl" scale="0.001 0.001 0.001"/>
    </geometry>
    <material name="gray"/>
  </visual>
  <collision>
    <origin xyz="0 0 0" rpy="0 0 0"/>
    <geometry>
      <mesh filename="package://maze_bot/meshes/base_link.stl" scale="0.001 0.001 0.001"/>
    </geometry>
  </collision>
</link>

<link name="right_wheel_1">
  <inertial>
    <origin xyz="-1.8346435481930712e-14 -0.012499999999999997 0.0" rpy="0 0 0"/>
    <mass value="0.17543149376634687"/>
    <inertia ixx="0.000119" iyy="0.000221" izz="0.000119" ixy="0.0" iyz="0.0" ixz="0.0"/>
  </inertial>
  <visual>
    <origin xyz="0.1 0.11 -0.05" rpy="0 0 0"/>
    <geometry>
      <mesh filename="package://maze_bot/meshes/right_wheel_1.stl" scale="0.001 0.001 0.001"/>
    </geometry>
    <material name="white"/>
  </visual>
  <collision>
    <origin xyz="0.1 0.11 -0.05" rpy="0 0 0"/>
    <geometry>
      <mesh filename="package://maze_bot/meshes/right_wheel_1.stl" scale="0.001 0.001 0.001"/>
    </geometry>
  </collision>
</link>

<link name="left_wheel_1">
  <inertial>
    <origin xyz="-1.8346435481930712e-14 0.012499999999999997 0.0" rpy="0 0 0"/>
    <mass value="0.17543149376634687"/>
    <inertia ixx="0.000119" iyy="0.000221" izz="0.000119" ixy="-0.0" iyz="0.0" ixz="0.0"/>
  </inertial>
  <visual>
    <origin xyz="0.1 -0.11 -0.05" rpy="0 0 0"/>
    <geometry>
      <mesh filename="package://maze_bot/meshes/left_wheel_1.stl" scale="0.001 0.001 0.001"/>
    </geometry>
    <material name="white"/>
  </visual>
  <collision>
    <origin xyz="0.1 -0.11 -0.05" rpy="0 0 0"/>
    <geometry>
      <mesh filename="package://maze_bot/meshes/left_wheel_1.stl" scale="0.001 0.001 0.001"/>
    </geometry>
  </collision>
</link>

<link name="caster_1">
  <inertial>
    <origin xyz="1.3877787807814457e-17 0.0 -0.009374999999999998" rpy="0 0 0"/>
    <mass value="0.25689064927791533"/>
    <inertia ixx="4.2e-05" iyy="4.2e-05" izz="6.4e-05" ixy="0.0" iyz="0.0" ixz="0.0"/>
  </inertial>
  <visual>
    <origin xyz="-0.1 0.0 -0.025" rpy="0 0 0"/>
    <geometry>
      <mesh filename="package://maze_bot/meshes/caster_1.stl" scale="0.001 0.001 0.001"/>
    </geometry>
    <material name="black"/>
  </visual>
  <collision>
    <origin xyz="-0.1 0.0 -0.025" rpy="0 0 0"/>
    <geometry>
      <mesh filename="package://maze_bot/meshes/caster_1.stl" scale="0.001 0.001 0.001"/>
    </geometry>
  </collision>
</link>

<link name="lidar_1">
  <inertial>
    <origin xyz="1.3877787807814457e-17 0.0 0.012499999999999983" rpy="0 0 0"/>
    <mass value="1.541343895667491"/>
    <inertia ixx="0.001044" iyy="0.001044" izz="0.001927" ixy="-0.0" iyz="-0.0" ixz="0.0"/>
  </inertial>
  <visual>
    <origin xyz="0.05 -0.0 -0.125" rpy="0 0 0"/>
    <geometry>
      <mesh filename="package://maze_bot/meshes/lidar_1.stl" scale="0.001 0.001 0.001"/>
    </geometry>
    <material name="gray"/>
  </visual>
  <collision>
    <origin xyz="0.05 -0.0 -0.125" rpy="0 0 0"/>
    <geometry>
      <mesh filename="package://maze_bot/meshes/lidar_1.stl" scale="0.001 0.001 0.001"/>
    </geometry>
  </collision>
</link>

<link name="camera_1">
  <inertial>
    <origin xyz="0.004999999999999949 5.228400754468975e-13 -1.3877787807814457e-17" rpy="0 0 0"/>
    <mass value="0.0010288715940507016"/>
    <inertia ixx="0.0" iyy="0.0" izz="0.0" ixy="0.0" iyz="0.0" ixz="-0.0"/>
  </inertial>
  <visual>
    <origin xyz="-0.16 -0.0 -0.05" rpy="0 0 0"/>
    <geometry>
      <mesh filename="package://maze_bot/meshes/camera_1.stl" scale="0.001 0.001 0.001"/>
    </geometry>
    <material name="gray"/>
  </visual>
  <collision>
    <origin xyz="-0.16 -0.0 -0.05" rpy="0 0 0"/>
    <geometry>
      <mesh filename="package://maze_bot/meshes/camera_1.stl" scale="0.001 0.001 0.001"/>
    </geometry>
  </collision>
</link>

<joint name="Revolute 1" type="continuous">
  <origin xyz="-0.1 -0.11 0.05" rpy="0 0 0"/>
  <parent link="base_link"/>
  <child link="right_wheel_1"/>
  <axis xyz="0.0 1.0 0.0"/>
</joint>

<joint name="Revolute 2" type="continuous">
  <origin xyz="-0.1 0.11 0.05" rpy="0 0 0"/>
  <parent link="base_link"/>
  <child link="left_wheel_1"/>
  <axis xyz="0.0 1.0 0.0"/>
</joint>

<joint name="Rigid 3" type="fixed">
  <origin xyz="0.1 0.0 0.025" rpy="0 0 0"/>
  <parent link="base_link"/>
  <child link="caster_1"/>
</joint>

<joint name="Rigid 4" type="fixed">
  <origin xyz="-0.05 0.0 0.125" rpy="0 0 0"/>
  <parent link="base_link"/>
  <child link="lidar_1"/>
</joint>

<joint name="Rigid 5" type="fixed">
  <origin xyz="0.16 0.0 0.05" rpy="0 0 0"/>
  <parent link="base_link"/>
  <child link="camera_1"/>
</joint>

<gazebo reference="base_link">
  <material>${body_color}</material>
  <mu1>0.2</mu1>
  <mu2>0.2</mu2>
  <selfCollide>true</selfCollide>
  <gravity>true</gravity>
</gazebo>

<gazebo reference="right_wheel_1">
  <material>${body_color}</material>
  <mu1>15000</mu1>
  <mu2>15000</mu2>
  <selfCollide>true</selfCollide>
</gazebo>

<gazebo reference="left_wheel_1">
  <material>${body_color}</material>
  <mu1>15000</mu1>
  <mu2>15000</mu2>
  <selfCollide>true</selfCollide>
</gazebo>

<gazebo reference="caster_1">
  <material>${body_color}</material>
  <mu1>0.01</mu1>
  <mu2>0.01</mu2>
  <selfCollide>true</selfCollide>
</gazebo>

<gazebo reference="lidar_1">
  <material>${body_color}</material>
  <mu1>0.2</mu1>
  <mu2>0.2</mu2>
  <selfCollide>true</selfCollide>
</gazebo>

<gazebo reference="camera_1">
  <material>${body_color}</material>
  <mu1>0.2</mu1>
  <mu2>0.2</mu2>
  <selfCollide>true</selfCollide>
</gazebo>

<gazebo>
  <plugin filename="libgazebo_ros_diff_drive.so" name="gazebo_base_controller">
    <odometry_frame>odom</odometry_frame>
    <commandTopic>cmd_vel</commandTopic>
    <publish_odom>true</publish_odom>
    <publish_odom_tf>true</publish_odom_tf>
    <update_rate>15.0</update_rate>
    <left_joint>Revolute 2</left_joint>
    <right_joint>Revolute 1</right_joint>
    <wheel_separation>0.12</wheel_separation>
    <wheel_diameter>0.1</wheel_diameter>
    <max_wheel_acceleration>1.0</max_wheel_acceleration>
    <robotBaseFrame>base_link</robotBaseFrame>

  </plugin>
</gazebo>

<gazebo reference="lidar_1">
    <sensor name="gazebo_lidar" type="ray">
      <visualize>false</visualize>
      <update_rate>12.0</update_rate>
      <plugin filename="libgazebo_ros_ray_sensor.so" name="gazebo_lidar">
      <ros>
        <remapping>~/out:=scan</remapping>
      </ros>
      
      <output_type>sensor_msgs/LaserScan</output_type>
      <frame_name>lidar_1</frame_name>
      </plugin>
      <ray>
        <scan>
          <horizontal>
            <samples>360</samples>
            <resolution>1</resolution>
            <min_angle>-3.14</min_angle>
            <max_angle>3.14</max_angle>
          </horizontal>
        </scan>
        <range>
          <min>0.120</min>
          <max>3.5</max>
          <resolution>0.015</resolution>
        </range>
        <noise>
          <type>gaussian</type>
          <mean>0.0</mean>
          <stddev>0.01</stddev>
        </noise>
      </ray>
    </sensor>
    <material>Gazebo/DarkGrey</material>
</gazebo> 


<gazebo reference="camera_1">
  <sensor type="camera" name="camera1">
    <update_rate>30.0</update_rate>
    <camera name="head">
      <horizontal_fov>1.3962634</horizontal_fov>
      <image>
        <width>800</width>
        <height>800</height>
        <format>R8G8B8</format>
      </image>
      <clip>
        <near>0.02</near>
        <far>300</far>
      </clip>
      <noise>
        <type>gaussian</type>
        <mean>0.0</mean>
        <stddev>0.007</stddev>
      </noise>
    </camera>
    <plugin name="camera_controller" filename="libgazebo_ros_camera.so">
      <alwaysOn>true</alwaysOn>
      <updateRate>0.0</updateRate>
      <cameraName>/camera</cameraName>
      <imageTopicName>image_raw</imageTopicName>
      <cameraInfoTopicName>camera_info</cameraInfoTopicName>
      <frameName>camera_1</frameName>
      <hackBaseline>0.07</hackBaseline>
    </plugin>
  </sensor>
  <material>Gazebo/Blue</material>
</gazebo>




  <gazebo reference="base_link">
      <material>Gazebo/Black</material>
    </gazebo>
    <gazebo reference="caster_1">
      <material>Gazebo/White</material>
    </gazebo>
    
    <gazebo reference="right_wheel_1">
      <material>Gazebo/Orange</material>
    </gazebo>
    <gazebo reference="left_wheel_1">
      <material>Gazebo/Orange</material>
    </gazebo>  


    
</robot>
